Workbook

Sheet Population frame
A1: saq14 | B1: saq01 | C1: pw_w4
A2: RURAL | B2: TIGRAY | C2: 895069.9
A3: URBAN | B3: TIGRAY | C3: 475317.2
A4: RURAL | B4: AFAR | C4: 119646.5
A5: URBAN | B5: AFAR | C5: 68430.72
A6: RURAL | B6: AMHARA | C6: 3601905
A7: URBAN | B7: AMHARA | C7: 1447288
A8: RURAL | B8: OROMIA | C8: 5179729
A9: URBAN | B9: OROMIA | C9: 2082420
A10: RURAL | B10: SOMALI | C10: 636652.5
A11: URBAN | B11: SOMALI | C11: 243110.2
A12: RURAL | B12: BENISHANGUL GUMUZ | C12: 133286
A13: URBAN | B13: BENISHANGUL GUMUZ | C13: 70373.22
... A22: URBAN | B22: DIRE DAWA | C22: 72107.05
A25: ESS4 | E25: ESS3 | H25: ESS3
A26: RURAL | E26: Rural | H26: All
A27: saq01 | B27: pw_w4 | E27: saq01 | F27: pw_w3 | H27: saq01 | I27: pw_w3
A28: TIGRAY RURAL | B28: 895069.9 | E28: Tigray | F28: 819105.1 | H28: Tigray | I28: 417421.4
A29: AFAR RURAL | B29: 119646.5 | E29: Afar | F29: 114269.8 | H29: Afar | I29: 88922.29
A30: AMHARA RURAL | B30: 3601905 | E30: Amhara | F30: 4214204 | H30: Amhara | I30: 1302109
A31: OROMIA RURAL | B31: 5179729 | E31: Oromia | F31: 5778682 | H31: Oromia | I31: 1529435
A32: SOMALI RURAL | B32: 636652.5 | E32: Somalie | F32: 373592.7 | H32: Somalie | I32: 91088.85
A33: BENISHANGUL GUMUZ RURAL | B33: 133286 | E33: Benshagul Gumuz | F33: 199104.7 | H33: Benshagul Gumuz | I33: 49615.38
A34: SNNP RURAL | B34: 2883768 | E34: SNNP | F34: 2999787 | H34: SNNP | I34: 812148.3
A35: GAMBELA RURAL | B35: 44190.8 | E35: Gambelia | F35: 58821.17 | H35: Gambelia | I35: 37639.51
A36: HARAR RURAL | B36: 27358.6 | E36: Harari | F36: 20128.73 | H36: Harari | I36: 39194.84
A37: DIRE DAWA RURAL | B37: 31211.51 | E37: Diredwa | F37: 36358.3 | H37: Addis Ababa | I37: 936066.6
B38: =SUM(B28:B37) -> 13552818 | E38: Other regions | F38: =+SUM(F29,F32,F33,F35,F36,F37) -> 802275.4 | H38: Diredwa | I38: 97382.58

Sheet ESS4_rural
B1: Tigray | E1: Amhara | H1: Oromia | K1: SNNP | N1: Afar | Q1: Somali | T1: Benshangul Gumuz | W1: Gambela | Z1: Harar | AC1: Dire Dawa
B2: Percentage | C2: Mean | D2: Nb of households | E2: Percentage | F2: Mean | G2: Nb of households | H2: Percentage | I2: Mean | J2: Nb of households | K2: Percentage | L2: Mean | M2: Nb of households | N2: Percentage | P2: Nb of households | Q2: Percentage | S2: Nb of households | T2: Percentage | V2: Nb of households | W2: Percentage | Y2: Nb of households | Z2: Percentage | AB2: Nb of households | AC2: Percentage | AE2: Nb of households
A3: Sweet potato OFSP variety | B3: 0 | C3: =B3/100 -> 0 | D3: =C3*'Population frame'!$B$28 -> 0 | E3: 0 | F3: =E3/100 -> 0 | G3: =F3*'Population frame'!$B$30 -> 0 | H3: 1.1943948 | I3: =+H3/100 -> 0.011943948 | J3: =I3*'Population frame'!$B$31 -> 61866.411 | K3: 2.1793828 | L3: =K3/100 -> 0.021793828 | M3: =L3*'Population frame'!$B$34 -> 62848.344 | N3: 0 | P3: =(N3*'Population frame'!$B$29)/100 -> 0 | Q3: 0 | S3: =(Q3*'Population frame'!$B$32)/100 -> 0 | T3: 5.7517706 | V3: =(T3*'Population frame'!$B$33)/100 -> 7666.305 | W3: 0 | Y3: =(W3*'Population frame'!$B$35)/100 -> 0 | Z3: 1.351051 | AB3: =(Z3*'Population frame'!$B$36)/100 -> 369.62863 | AC3: 1.1586882 | AE3: =(AC3*'Population frame'!$B$37)/100 -> 361.64408
A4: Sweet potato Awassa83 variety | B4: 0 | C4: =B4/100 -> 0 | D4: =C4*'Population frame'!$B$28 -> 0 | E4: 0 | F4: =E4/100 -> 0 | G4: =F4*'Population frame'!$B$30 -> 0 | H4: 1.2649716 | I4: =+H4/100 -> 0.012649716 | J4: =I4*'Population frame'!$B$31 -> 65522.1 | K4: 12.730843 | L4: =K4/100 -> 0.12730843 | M4: =L4*'Population frame'!$B$34 -> 367127.97 | N4: 0 | P4: =(N4*'Population frame'!$B$29)/100 -> 0 | Q4: 0 | S4: =(Q4*'Population frame'!$B$32)/100 -> 0 | T4: 1.6039459 | V4: =(T4*'Population frame'!$B$33)/100 -> 2137.8354 | W4: 0.47833114 | Y4: =(W4*'Population frame'!$B$35)/100 -> 211.37836 | Z4: 0.46448248 | AB4: =(Z4*'Population frame'!$B$36)/100 -> 127.0759 | AC4: 4.2375151 | AE4: =(AC4*'Population frame'!$B$37)/100 -> 1322.5925
A5: Avocado tree | B5: 0.51481485 | C5: =B5/100 -> 0.0051481485 | D5: =C5*'Population frame'!$B$28 -> 4607.9528 | E5: 0 | F5: =E5/100 -> 0 | G5: =F5*'Population frame'!$B$30 -> 0 | H5: 9.9028287 | I5: =+H5/100 -> 0.099028287 | J5: =I5*'Population frame'!$B$31 -> 512939.69 | K5: 27.42026 | L5: =K5/100 -> 0.2742026 | M5: =L5*'Population frame'!$B$34 -> 790736.69 | N5: 0 | P5: =(N5*'Population frame'!$B$29)/100 -> 0 | Q5: 0 | S5: =(Q5*'Population frame'!$B$32)/100 -> 0 | T5: 5.3022662 | V5: =(T5*'Population frame'!$B$33)/100 -> 7067.1785 | W5: 16.26618 | Y5: =(W5*'Population frame'!$B$35)/100 -> 7188.155 | Z5: 1.2907406 | AB5: =(Z5*'Population frame'!$B$36)/100 -> 353.12855 | AC5: 0 | AE5: =(AC5*'Population frame'!$B$37)/100 -> 0
A6: Papaya tree | B6: 0.61033152 | C6: =B6/100 -> 0.0061033152 | D6: =C6*'Population frame'!$B$28 -> 5462.8937 | E6: 1.8844188 | F6: =E6/100 -> 0.018844188 | G6: =F6*'Population frame'!$B$30 -> 67874.976 | H6: 3.3034054 | I6: =+H6/100 -> 0.033034054 | J6: =I6*'Population frame'!$B$31 -> 171107.45 | K6: 8.9469805 | L6: =K6/100 -> 0.089469805 | M6: =L6*'Population frame'!$B$34 -> 258010.16 | N6: 0 | P6: =(N6*'Population frame'!$B$29)/100 -> 0 | Q6: 0 | S6: =(Q6*'Population frame'!$B$32)/100 -> 0 | T6: 17.886415 | V6: =(T6*'Population frame'!$B$33)/100 -> 23840.087 | W6: 15.593226 | Y6: =(W6*'Population frame'!$B$35)/100 -> 6890.7712 | Z6: 8.8314811 | AB6: =(Z6*'Population frame'!$B$36)/100 -> 2416.1696 | AC6: 9.1583033 | AE6: =(AC6*'Population frame'!$B$37)/100 -> 2858.4447
A7: Mango tree | B7: 1.72704 | C7: =B7/100 -> 0.0172704 | D7: =C7*'Population frame'!$B$28 -> 15458.215 | E7: 5.3297709 | F7: =E7/100 -> 0.053297709 | G7: =F7*'Population frame'!$B$30 -> 191973.28 | H7: 8.9140398 | I7: =+H7/100 -> 0.089140398 | J7: =I7*'Population frame'!$B$31 -> 461723.11 | K7: 16.663042 | L7: =K7/100 -> 0.16663042 | M7: =L7*'Population frame'!$B$34 -> 480523.46 | N7: 0 | P7: =(N7*'Population frame'!$B$29)/100 -> 0 | Q7: 0 | S7: =(Q7*'Population frame'!$B$32)/100 -> 0 | T7: 51.285201 | V7: =(T7*'Population frame'!$B$33)/100 -> 68355.993 | W7: 18.500047 | Y7: =(W7*'Population frame'!$B$35)/100 -> 8175.3188 | Z7: 37.312637 | AB7: =(Z7*'Population frame'!$B$36)/100 -> 10208.215 | AC7: 3.1929966 | AE7: =(AC7*'Population frame'!$B$37)/100 -> 996.58246
A8: Field peas | B8: 5.1059774 | C8: =B8/100 -> 0.051059774 | D8: =C8*'Population frame'!$B$28 -> 45702.067 | E8: 14.654484 | F8: =E8/100 -> 0.14654484 | G8: =F8*'Population frame'!$B$30 -> 527840.58 | H8: 6.1595951 | I8: =+H8/100 -> 0.061595951 | J8: =I8*'Population frame'!$B$31 -> 319050.33 | K8: 8.0165212 | L8: =K8/100 -> 0.080165212 | M8: =L8*'Population frame'!$B$34 -> 231177.87 | N8: 0 | P8: =(N8*'Population frame'!$B$29)/100 -> 0 | Q8: 0 | S8: =(Q8*'Population frame'!$B$32)/100 -> 0 | T8: 2.6104213 | V8: =(T8*'Population frame'!$B$33)/100 -> 3479.3262 | W8: 0 | Y8: =(W8*'Population frame'!$B$35)/100 -> 0 | Z8: 0.46448248 | AB8: =(Z8*'Population frame'!$B$36)/100 -> 127.0759 | AC8: 0 | AE8: =(AC8*'Population frame'!$B$37)/100 -> 0
A9: Sweetpotato | B9: 0 | C9: =B9/100 -> 0 | D9: =C9*'Population frame'!$B$28 -> 0 | E9: 0.23178065 | F9: =E9/100 -> 0.0023178065 | G9: =F9*'Population frame'!$B$30 -> 8348.5188 | H9: 6.4206088 | I9: =+H9/100 -> 0.064206088 | J9: =I9*'Population frame'!$B$31 -> 332570.14 | K9: 16.419134 | L9: =K9/100 -> 0.16419134 | M9: =L9*'Population frame'!$B$34 -> 473489.73 | N9: 0 | P9: =(N9*'Population frame'!$B$29)/100 -> 0 | Q9: 0 | S9: =(Q9*'Population frame'!$B$32)/100 -> 0 | T9: 14.104531 | V9: =(T9*'Population frame'!$B$33)/100 -> 18799.365 | W9: 5.9024865 | Y9: =(W9*'Population frame'!$B$35)/100 -> 2608.356 | Z9: 4.8200269 | AB9: =(Z9*'Population frame'!$B$36)/100 -> 1318.6919 | AC9: 10.660039 | AE9: =(AC9*'Population frame'!$B$37)/100 -> 3327.1591
A10: Improved BARLEY-SR | B10: 6.2474474 | C10: =B10/100 -> 0.062474474 | D10: =C10*'Population frame'!$B$28 -> 55919.021 | E10: 0 | F10: =E10/100 -> 0 | G10: =F10*'Population frame'!$B$30 -> 0 | H10: 7.5724921 | I10: =+H10/100 -> 0.075724921 | J10: =I10*'Population frame'!$B$31 -> 392234.57 | K10: 8.3105873 | L10: =K10/100 -> 0.083105873 | M10: =L10*'Population frame'!$B$34 -> 239658.06 | N10: 0 | P10: =(N10*'Population frame'!$B$29)/100 -> 0 | Q10: 0 | S10: =(Q10*'Population frame'!$B$32)/100 -> 0 | T10: 0 | V10: =(T10*'Population frame'!$B$33)/100 -> 0 | W10: 0 | Y10: =(W10*'Population frame'!$B$35)/100 -> 0 | Z10: 0 | AB10: =(Z10*'Population frame'!$B$36)/100 -> 0 | AC10: 0 | AE10: =(AC10*'Population frame'!$B$37)/100 -> 0
A11: Improved MAIZE-SR | B11: 15.792874 | C11: =B11/100 -> 0.15792874 | D11: =C11*'Population frame'!$B$28 -> 141357.26 | E11: 34.022528 | F11: =E11/100 -> 0.34022528 | G11: =F11*'Population frame'!$B$30 -> 1225459.1 | H11: 56.849055 | I11: =+H11/100 -> 0.56849055 | J11: =I11*'Population frame'!$B$31 -> 2944627 | K11: 40.88017 | L11: =K11/100 -> 0.4088017 | M11: =L11*'Population frame'!$B$34 -> 1178889.3 | N11: 50.454973 | P11: =(N11*'Population frame'!$B$29)/100 -> 60367.609 | Q11: 0 | S11: =(Q11*'Population frame'!$B$32)/100 -> 0 | T11: 18.142098 | V11: =(T11*'Population frame'!$B$33)/100 -> 24180.877 | W11: 0 | Y11: =(W11*'Population frame'!$B$35)/100 -> 0 | Z11: 35.043457 | AB11: =(Z11*'Population frame'!$B$36)/100 -> 9587.3993 | AC11: 3.2123566 | AE11: =(AC11*'Population frame'!$B$37)/100 -> 1002.625
A12: Improved MILLET-SR | B12: 1.358921 | C12: =B12/100 -> 0.01358921 | D12: =C12*'Population frame'!$B$28 -> 12163.292 | E12: 0 | F12: =E12/100 -> 0 | G12: =F12*'Population frame'!$B$30 -> 0 | H12: 0 | I12: =+H12/100 -> 0 | J12: =I12*'Population frame'!$B$31 -> 0 | K12: 11.967491 | L12: =K12/100 -> 0.11967491 | M12: =L12*'Population frame'!$B$34 -> 345114.66 | N12: 0 | P12: =(N12*'Population frame'!$B$29)/100 -> 0 | Q12: 0 | S12: =(Q12*'Population frame'!$B$32)/100 -> 0 | T12: 2.344878 | V12: =(T12*'Population frame'!$B$33)/100 -> 3125.3941 | W12: 0 | Y12: =(W12*'Population frame'!$B$35)/100 -> 0 | Z12: 0 | AB12: =(Z12*'Population frame'!$B$36)/100 -> 0 | AC12: 0 | AE12: =(AC12*'Population frame'!$B$37)/100 -> 0
A13: Improved OATS-SR | B13: 0 | C13: =B13/100 -> 0 | D13: =C13*'Population frame'!$B$28 -> 0 | E13: 0 | F13: =E13/100 -> 0 | G13: =F13*'Population frame'!$B$30 -> 0 | H13: 0 | I13: =+H13/100 -> 0 | J13: =I13*'Population frame'!$B$31 -> 0 | K13: 0 | L13: =K13/100 -> 0 | M13: =L13*'Population frame'!$B$34 -> 0 | N13: 0 | P13: =(N13*'Population frame'!$B$29)/100 -> 0 | Q13: 0 | S13: =(Q13*'Population frame'!$B$32)/100 -> 0 | T13: 0 | V13: =(T13*'Population frame'!$B$33)/100 -> 0 | W13: 0 | Y13: =(W13*'Population frame'!$B$35)/100 -> 0 | Z13: 0 | AB13: =(Z13*'Population frame'!$B$36)/100 -> 0 | AC13: 0 | AE13: =(AC13*'Population frame'!$B$37)/100 -> 0
A14: Improved RICE-SR | B14: 0 | C14: =B14/100 -> 0 | D14: =C14*'Population frame'!$B$28 -> 0 | E14: 7.0882684 | F14: =E14/100 -> 0.070882684 | G14: =F14*'Population frame'!$B$30 -> 255312.69 | H14: 0 | I14: =+H14/100 -> 0 | J14: =I14*'Population frame'!$B$31 -> 0 | K14: 0 | L14: =K14/100 -> 0 | M14: =L14*'Population frame'!$B$34 -> 0 | N14: 0 | P14: =(N14*'Population frame'!$B$29)/100 -> 0 | Q14: 0 | S14: =(Q14*'Population frame'!$B$32)/100 -> 0 | T14: 0 | V14: =(T14*'Population frame'!$B$33)/100 -> 0 | W14: 0 | Y14: =(W14*'Population frame'!$B$35)/100 -> 0 | Z14: 0 | AB14: =(Z14*'Population frame'!$B$36)/100 -> 0 | AC14: 0 | AE14: =(AC14*'Population frame'!$B$37)/100 -> 0
... A41: Improved (SR) cash crop | B41: 0 | C41: =B41/100 -> 0 | D41: =C41*'Population frame'!$B$28 -> 0 | E41: 100 | F41: =E41/100 -> 1 | G41: =F41*'Population frame'!$B$30 -> 3601905 | H41: 0 | I41: =+H41/100 -> 0 | J41: =I41*'Population frame'!$B$31 -> 0 | K41: 1.7563329 | L41: =K41/100 -> 0.017563329 | M41: =L41*'Population frame'!$B$34 -> 50648.566 | N41: 0 | P41: =(N41*'Population frame'!$B$29)/100 -> 0 | Q41: 0 | S41: =(Q41*'Population frame'!$B$32)/100 -> 0 | T41: 0 | V41: =(T41*'Population frame'!$B$33)/100 -> 0 | W41: 0 | Y41: =(W41*'Population frame'!$B$35)/100 -> 0 | Z41: 0 | AB41: =(Z41*'Population frame'!$B$36)/100 -> 0 | AC41: 0 | AE41: =(AC41*'Population frame'!$B$37)/100 -> 0
M42: =L42*'Population frame'!$B$34 -> 0
A43: River dispersion | B43: 4.8774409 | C43: =B43/100 -> 0.048774409 | D43: =C43*'Population frame'!$B$28 -> 43656.506 | E43: 8.7015062 | F43: =E43/100 -> 0.087015062 | G43: =F43*'Population frame'!$B$30 -> 313419.99 | H43: 4.4826904 | I43: =+H43/100 -> 0.044826904 | J43: =I43*'Population frame'!$B$31 -> 232191.22 | K43: 0.49368373 | L43: =K43/100 -> 0.0049368373 | M43: =L43*'Population frame'!$B$34 -> 14236.693 | N43: 49.2761 | P43: =(N43*'Population frame'!$B$29)/100 -> 58957.129 | Q43: 0 | S43: =(Q43*'Population frame'!$B$32)/100 -> 0 | T43: 9.7038888 | V43: =(T43*'Population frame'!$B$33)/100 -> 12933.925 | W43: 0 | Y43: =(W43*'Population frame'!$B$35)/100 -> 0 | Z43: 6.4788833 | AB43: =(Z43*'Population frame'!$B$36)/100 -> 1772.5318 | AC43: 25.568962 | AE43: =(AC43*'Population frame'!$B$37)/100 -> 7980.459
A44: Treadle pump used for irrigation | B44: 0 | C44: =B44/100 -> 0 | D44: =C44*'Population frame'!$B$28 -> 0 | E44: 0.2581397 | F44: =E44/100 -> 0.002581397 | G44: =F44*'Population frame'!$B$30 -> 9297.9467 | H44: 0 | I44: =+H44/100 -> 0 | J44: =I44*'Population frame'!$B$31 -> 0 | K44: 0 | L44: =K44/100 -> 0 | M44: =L44*'Population frame'!$B$34 -> 0 | N44: 0 | P44: =(N44*'Population frame'!$B$29)/100 -> 0 | Q44: 0 | S44: =(Q44*'Population frame'!$B$32)/100 -> 0 | T44: 0 | V44: =(T44*'Population frame'!$B$33)/100 -> 0 | W44: 0 | Y44: =(W44*'Population frame'!$B$35)/100 -> 0 | Z44: 0.43241107 | AB44: =(Z44*'Population frame'!$B$36)/100 -> 118.30162 | AC44: 0 | AE44: =(AC44*'Population frame'!$B$37)/100 -> 0
A45: Motor pump used for irrigation | B45: 1.0931503 | C45: =B45/100 -> 0.010931503 | D45: =C45*'Population frame'!$B$28 -> 9784.459 | E45: 1.6475626 | F45: =E45/100 -> 0.016475626 | G45: =F45*'Population frame'!$B$30 -> 59343.641 | H45: 1.5685475 | I45: =+H45/100 -> 0.015685475 | J45: =I45*'Population frame'!$B$31 -> 81246.507 | K45: 0 | L45: =K45/100 -> 0 | M45: =L45*'Population frame'!$B$34 -> 0 | N45: 12.59868 | P45: =(N45*'Population frame'!$B$29)/100 -> 15073.88 | Q45: 28.256071 | S45: =(Q45*'Population frame'!$B$32)/100 -> 179892.98 | T45: 0 | V45: =(T45*'Population frame'!$B$33)/100 -> 0 | W45: 1.0792534 | Y45: =(W45*'Population frame'!$B$35)/100 -> 476.93073 | Z45: 17.293877 | AB45: =(Z45*'Population frame'!$B$36)/100 -> 4731.3627 | AC45: 1.1653989 | AE45: =(AC45*'Population frame'!$B$37)/100 -> 363.73859
A46: Crop rotation with a legume | B46: 53.23335 | C46: =B46/100 -> 0.5323335 | D46: =C46*'Population frame'!$B$28 -> 476475.69 | E46: 73.206214 | F46: =E46/100 -> 0.73206214 | G46: =F46*'Population frame'!$B$30 -> 2636818.3 | H46: 47.456476 | I46: =+H46/100 -> 0.47456476 | J46: =I46*'Population frame'!$B$31 -> 2458116.9 | K46: 52.191743 | L46: =K46/100 -> 0.52191743 | M46: =L46*'Population frame'!$B$34 -> 1505088.8 | N46: 0 | P46: =(N46*'Population frame'!$B$29)/100 -> 0 | Q46: 0 | S46: =(Q46*'Population frame'!$B$32)/100 -> 0 | T46: 52.714298 | V46: =(T46*'Population frame'!$B$33)/100 -> 70260.78 | W46: 4.5367499 | Y46: =(W46*'Population frame'!$B$35)/100 -> 2004.8261 | Z46: 9.9623889 | AB46: =(Z46*'Population frame'!$B$36)/100 -> 2725.5701 | AC46: 30.437875 | AE46: =(AC46*'Population frame'!$B$37)/100 -> 9500.1205
A47: Crop residue cover - farmer alicitation | B47: 0.8040354 | C47: =B47/100 -> 0.008040354 | D47: =C47*'Population frame'!$B$28 -> 7196.6788 | E47: 4.5974517 | F47: =E47/100 -> 0.045974517 | G47: =F47*'Population frame'!$B$30 -> 165595.84 | H47: 3.527098 | I47: =+H47/100 -> 0.03527098 | J47: =I47*'Population frame'!$B$31 -> 182694.12 | K47: 8.0237477 | L47: =K47/100 -> 0.080237477 | M47: =L47*'Population frame'!$B$34 -> 231386.27 | N47: 3.1188587 | P47: =(N47*'Population frame'!$B$29)/100 -> 3731.6052 | Q47: 0 | S47: =(Q47*'Population frame'!$B$32)/100 -> 0 | T47: 7.6115954 | V47: =(T47*'Population frame'!$B$33)/100 -> 10145.191 | W47: 0 | Y47: =(W47*'Population frame'!$B$35)/100 -> 0 | Z47: 28.412549 | AB47: =(Z47*'Population frame'!$B$36)/100 -> 7773.2755 | AC47: 4.2177087 | AE47: =(AC47*'Population frame'!$B$37)/100 -> 1316.4106
A48: Crop residue cover - visual aid | B48: 30.024974 | C48: =B48/100 -> 0.30024974 | D48: =C48*'Population frame'!$B$28 -> 268744.5 | E48: 34.017674 | F48: =E48/100 -> 0.34017674 | G48: =F48*'Population frame'!$B$30 -> 1225284.3 | H48: 36.404559 | I48: =+H48/100 -> 0.36404559 | J48: =I48*'Population frame'!$B$31 -> 1885657.5 | K48: 79.167635 | L48: =K48/100 -> 0.79167635 | M48: =L48*'Population frame'!$B$34 -> 2283010.9 | N48: 45.029476 | P48: =(N48*'Population frame'!$B$29)/100 -> 53876.192 | Q48: 60 | S48: =(Q48*'Population frame'!$B$32)/100 -> 381991.5 | T48: 90.447733 | V48: =(T48*'Population frame'!$B$33)/100 -> 120554.17 | W48: 68.045876 | Y48: =(W48*'Population frame'!$B$35)/100 -> 30070.017 | Z48: 73.013121 | AB48: =(Z48*'Population frame'!$B$36)/100 -> 19975.368 | AC48: 61.628444 | AE48: =(AC48*'Population frame'!$B$37)/100 -> 19235.168
A49: Minimum tillage | B49: 36.935678 | C49: =B49/100 -> 0.36935678 | D49: =C49*'Population frame'!$B$28 -> 330600.14 | E49: 51.432749 | F49: =E49/100 -> 0.51432749 | G49: =F49*'Population frame'!$B$30 -> 1852558.8 | H49: 41.597762 | I49: =+H49/100 -> 0.41597762 | J49: =I49*'Population frame'!$B$31 -> 2154651.4 | K49: 57.440279 | L49: =K49/100 -> 0.57440279 | M49: =L49*'Population frame'!$B$34 -> 1656444.4 | N49: 22.879736 | P49: =(N49*'Population frame'!$B$29)/100 -> 27374.803 | Q49: 100 | S49: =(Q49*'Population frame'!$B$32)/100 -> 636652.5 | T49: 66.684085 | V49: =(T49*'Population frame'!$B$33)/100 -> 88880.549 | W49: 93.143807 | Y49: =(W49*'Population frame'!$B$35)/100 -> 41160.993 | Z49: 38.174622 | AB49: =(Z49*'Population frame'!$B$36)/100 -> 10444.042 | AC49: 85.979991 | AE49: =(AC49*'Population frame'!$B$37)/100 -> 26835.653
A50: Zero tillage | B50: 11.74376 | C50: =B50/100 -> 0.1174376 | D50: =C50*'Population frame'!$B$28 -> 105114.86 | E50: 12.052479 | F50: =E50/100 -> 0.12052479 | G50: =F50*'Population frame'!$B$30 -> 434118.85 | H50: 8.3585497 | I50: =+H50/100 -> 0.083585497 | J50: =I50*'Population frame'!$B$31 -> 432950.22 | K50: 18.184707 | L50: =K50/100 -> 0.18184707 | M50: =L50*'Population frame'!$B$34 -> 524404.76 | N50: 0 | P50: =(N50*'Population frame'!$B$29)/100 -> 0 | Q50: 0 | S50: =(Q50*'Population frame'!$B$32)/100 -> 0 | T50: 9.6459828 | V50: =(T50*'Population frame'!$B$33)/100 -> 12856.745 | W50: 60.358656 | Y50: =(W50*'Population frame'!$B$35)/100 -> 26672.973 | Z50: 4.4695603 | AB50: =(Z50*'Population frame'!$B$36)/100 -> 1222.8091 | AC50: 9.6899422 | AE50: =(AC50*'Population frame'!$B$37)/100 -> 3024.3773
A51: Conservation Agriculture - using Minimum tillage | B51: 1.9452585 | C51: =B51/100 -> 0.019452585 | D51: =C51*'Population frame'!$B$28 -> 17411.423 | E51: 4.3712552 | F51: =E51/100 -> 0.043712552 | G51: =F51*'Population frame'!$B$30 -> 157448.46 | H51: 4.0592453 | I51: =+H51/100 -> 0.040592453 | J51: =I51*'Population frame'!$B$31 -> 210257.91 | K51: 4.6600662 | L51: =K51/100 -> 0.046600662 | M51: =L51*'Population frame'!$B$34 -> 134385.5 | N51: 0 | P51: =(N51*'Population frame'!$B$29)/100 -> 0 | Q51: 0 | S51: =(Q51*'Population frame'!$B$32)/100 -> 0 | T51: 17.536753 | V51: =(T51*'Population frame'!$B$33)/100 -> 23374.036 | W51: 2.1923409 | Y51: =(W51*'Population frame'!$B$35)/100 -> 968.81298 | Z51: 0.74374014 | AB51: =(Z51*'Population frame'!$B$36)/100 -> 203.47689 | AC51: 19.824875 | AE51: =(AC51*'Population frame'!$B$37)/100 -> 6187.6429
A52: Conservation Agriculture - using Zero tillage | B52: 0.85549848 | C52: =B52/100 -> 0.0085549848 | D52: =C52*'Population frame'!$B$28 -> 7657.3093 | E52: 1.6316589 | F52: =E52/100 -> 0.016316589 | G52: =F52*'Population frame'!$B$30 -> 58770.804 | H52: 1.4874775 | I52: =+H52/100 -> 0.014874775 | J52: =I52*'Population frame'!$B$31 -> 77047.301 | K52: 0.46428694 | L52: =K52/100 -> 0.0046428694 | M52: =L52*'Population frame'!$B$34 -> 13388.958 | N52: 0 | P52: =(N52*'Population frame'!$B$29)/100 -> 0 | Q52: 0 | S52: =(Q52*'Population frame'!$B$32)/100 -> 0 | T52: 1.5725988 | V52: =(T52*'Population frame'!$B$33)/100 -> 2096.054 | W52: 0.9630633 | Y52: =(W52*'Population frame'!$B$35)/100 -> 425.58538 | Z52: 0 | AB52: =(Z52*'Population frame'!$B$36)/100 -> 0 | AC52: 7.1842424 | AE52: =(AC52*'Population frame'!$B$37)/100 -> 2242.3105
A53: Soil Water Conservation practices | B53: 87.23395 | C53: =B53/100 -> 0.8723395 | D53: =C53*'Population frame'!$B$28 -> 780804.83 | E53: 89.4316 | F53: =E53/100 -> 0.894316 | G53: =F53*'Population frame'!$B$30 -> 3221241.3 | H53: 63.66649 | I53: =+H53/100 -> 0.6366649 | J53: =I53*'Population frame'!$B$31 -> 3297751.6 | K53: 61.529655 | L53: =K53/100 -> 0.61529655 | M53: =L53*'Population frame'!$B$34 -> 1774372.5 | N53: 66.653915 | P53: =(N53*'Population frame'!$B$29)/100 -> 79749.077 | Q53: 19.919011 | S53: =(Q53*'Population frame'!$B$32)/100 -> 126814.88 | T53: 79.855628 | V53: =(T53*'Population frame'!$B$33)/100 -> 106436.37 | W53: 8.277197 | Y53: =(W53*'Population frame'!$B$35)/100 -> 3657.7596 | Z53: 91.828464 | AB53: =(Z53*'Population frame'!$B$36)/100 -> 25122.982 | AC53: 89.382985 | AE53: =(AC53*'Population frame'!$B$37)/100 -> 27897.779
A54: Terracing | B54: 39.657354 | C54: =B54/100 -> 0.39657354 | D54: =C54*'Population frame'!$B$28 -> 354961.04 | E54: 66.853539 | F54: =E54/100 -> 0.66853539 | G54: =F54*'Population frame'!$B$30 -> 2408001 | H54: 32.724816 | I54: =+H54/100 -> 0.32724816 | J54: =I54*'Population frame'!$B$31 -> 1695056.8 | K54: 38.360636 | L54: =K54/100 -> 0.38360636 | M54: =L54*'Population frame'!$B$34 -> 1106231.7 | N54: 21.526568 | P54: =(N54*'Population frame'!$B$29)/100 -> 25755.786 | Q54: 19.919011 | S54: =(Q54*'Population frame'!$B$32)/100 -> 126814.88 | T54: 26.999411 | V54: =(T54*'Population frame'!$B$33)/100 -> 35986.436 | W54: 0 | Y54: =(W54*'Population frame'!$B$35)/100 -> 0 | Z54: 78.338201 | AB54: =(Z54*'Population frame'!$B$36)/100 -> 21432.235 | AC54: 78.894395 | AE54: =(AC54*'Population frame'!$B$37)/100 -> 24624.132
... A60: Crossbred LARGE RUMINANTS | B60: 2.7013758 | C60: =B60/100 -> 0.027013758 | D60: =C60*'Population frame'!$B$28 -> 24179.202 | E60: 6.7625577 | F60: =E60/100 -> 0.067625577 | G60: =F60*'Population frame'!$B$30 -> 243580.9 | H60: 8.2444027 | I60: =+H60/100 -> 0.082444027 | J60: =I60*'Population frame'!$B$31 -> 427037.72 | K60: 5.3370941 | L60: =K60/100 -> 0.053370941 | M60: =L60*'Population frame'!$B$34 -> 153909.41 | N60: 0.097123047 | P60: =(N60*'Population frame'!$B$29)/100 -> 116.20433 | Q60: 0 | S60: =(Q60*'Population frame'!$B$32)/100 -> 0 | T60: 1.2678408 | V60: =(T60*'Population frame'!$B$33)/100 -> 1689.8543 | W60: 0 | Y60: =(W60*'Population frame'!$B$35)/100 -> 0 | Z60: 3.4095179 | AB60: =(Z60*'Population frame'!$B$36)/100 -> 932.79638 | AC60: 0 | AE60: =(AC60*'Population frame'!$B$37)/100 -> 0
A61: Crossbred SMALL RUMINANTS | B61: 0 | C61: =B61/100 -> 0 | D61: =C61*'Population frame'!$B$28 -> 0 | E61: 0 | F61: =E61/100 -> 0 | G61: =F61*'Population frame'!$B$30 -> 0 | H61: 0.66341105 | I61: =+H61/100 -> 0.0066341105 | J61: =I61*'Population frame'!$B$31 -> 34362.895 | K61: 0.28398137 | L61: =K61/100 -> 0.0028398137 | M61: =L61*'Population frame'!$B$34 -> 8189.3639 | N61: 0 | P61: =(N61*'Population frame'!$B$29)/100 -> 0 | Q61: 0 | S61: =(Q61*'Population frame'!$B$32)/100 -> 0 | T61: 0 | V61: =(T61*'Population frame'!$B$33)/100 -> 0 | W61: 0 | Y61: =(W61*'Population frame'!$B$35)/100 -> 0 | Z61: 0 | AB61: =(Z61*'Population frame'!$B$36)/100 -> 0 | AC61: 1.0213705 | AE61: =(AC61*'Population frame'!$B$37)/100 -> 318.78516 | AF61: =SUM(AE61,M61,J61) -> 42871.044
A62: Crossbred POULTRY | B62: 33.549719 | C62: =B62/100 -> 0.33549719 | D62: =C62*'Population frame'!$B$28 -> 300293.43 | E62: 14.516764 | F62: =E62/100 -> 0.14516764 | G62: =F62*'Population frame'!$B$30 -> 522880.04 | H62: 11.390195 | I62: =+H62/100 -> 0.11390195 | J62: =I62*'Population frame'!$B$31 -> 589981.22 | K62: 11.254633 | L62: =K62/100 -> 0.11254633 | M62: =L62*'Population frame'!$B$34 -> 324557.5 | N62: 0.73853158 | P62: =(N62*'Population frame'!$B$29)/100 -> 883.62719 | Q62: 0 | S62: =(Q62*'Population frame'!$B$32)/100 -> 0 | T62: 5.7341774 | V62: =(T62*'Population frame'!$B$33)/100 -> 7642.8557 | W62: 12.478241 | Y62: =(W62*'Population frame'!$B$35)/100 -> 5514.2345 | Z62: 1.7920908 | AB62: =(Z62*'Population frame'!$B$36)/100 -> 490.29095 | AC62: 18.444247 | AE62: =(AC62*'Population frame'!$B$37)/100 -> 5756.7279
A63: AI on any livestock type | B63: 0.8232068 | C63: =B63/100 -> 0.008232068 | D63: =C63*'Population frame'!$B$28 -> 7368.2762 | E63: 0.51245296 | F63: =E63/100 -> 0.0051245296 | G63: =F63*'Population frame'!$B$30 -> 18458.069 | H63: 1.6409693 | I63: =+H63/100 -> 0.016409693 | J63: =I63*'Population frame'!$B$31 -> 84997.764 | K63: 1.0841996 | L63: =K63/100 -> 0.010841996 | M63: =L63*'Population frame'!$B$34 -> 31265.802 | N63: 0 | P63: =(N63*'Population frame'!$B$29)/100 -> 0 | Q63: 0 | S63: =(Q63*'Population frame'!$B$32)/100 -> 0 | T63: 0 | V63: =(T63*'Population frame'!$B$33)/100 -> 0 | W63: 0 | Y63: =(W63*'Population frame'!$B$35)/100 -> 0 | Z63: 0 | AB63: =(Z63*'Population frame'!$B$36)/100 -> 0 | AC63: 0 | AE63: =(AC63*'Population frame'!$B$37)/100 -> 0
A64: Feed and Forage: Elephant Grass | B64: 0 | C64: =B64/100 -> 0 | D64: =C64*'Population frame'!$B$28 -> 0 | E64: 0 | F64: =E64/100 -> 0 | G64: =F64*'Population frame'!$B$30 -> 0 | H64: 0.22113702 | I64: =+H64/100 -> 0.0022113702 | J64: =I64*'Population frame'!$B$31 -> 11454.298 | K64: 1.6776494 | L64: =K64/100 -> 0.016776494 | M64: =L64*'Population frame'!$B$34 -> 48379.516 | N64: 0 | P64: =(N64*'Population frame'!$B$29)/100 -> 0 | Q64: 0 | S64: =(Q64*'Population frame'!$B$32)/100 -> 0 | T64: 0 | V64: =(T64*'Population frame'!$B$33)/100 -> 0 | W64: 0 | Y64: =(W64*'Population frame'!$B$35)/100 -> 0 | Z64: 0 | AB64: =(Z64*'Population frame'!$B$36)/100 -> 0 | AC64: 0 | AE64: =(AC64*'Population frame'!$B$37)/100 -> 0
A65: Feed and Forage: Gaya | B65: 0.39210628 | C65: =B65/100 -> 0.0039210628 | D65: =C65*'Population frame'!$B$28 -> 3509.6253 | E65: 0 | F65: =E65/100 -> 0 | G65: =F65*'Population frame'!$B$30 -> 0 | H65: 0 | I65: =+H65/100 -> 0 | J65: =I65*'Population frame'!$B$31 -> 0 | K65: 0 | L65: =K65/100 -> 0 | M65: =L65*'Population frame'!$B$34 -> 0 | N65: 0 | P65: =(N65*'Population frame'!$B$29)/100 -> 0 | Q65: 0 | S65: =(Q65*'Population frame'!$B$32)/100 -> 0 | T65: 0 | V65: =(T65*'Population frame'!$B$33)/100 -> 0 | W65: 0 | Y65: =(W65*'Population frame'!$B$35)/100 -> 0 | Z65: 0 | AB65: =(Z65*'Population frame'!$B$36)/100 -> 0 | AC65: 0 | AE65: =(AC65*'Population frame'!$B$37)/100 -> 0
A66: Feed and Forage: Sasbaniya | B66: 0 | C66: =B66/100 -> 0 | D66: =C66*'Population frame'!$B$28 -> 0 | E66: 0 | F66: =E66/100 -> 0 | G66: =F66*'Population frame'!$B$30 -> 0 | H66: 0 | I66: =+H66/100 -> 0 | J66: =I66*'Population frame'!$B$31 -> 0 | K66: 0 | L66: =K66/100 -> 0 | M66: =L66*'Population frame'!$B$34 -> 0 | N66: 0 | P66: =(N66*'Population frame'!$B$29)/100 -> 0 | Q66: 0 | S66: =(Q66*'Population frame'!$B$32)/100 -> 0 | T66: 0 | V66: =(T66*'Population frame'!$B$33)/100 -> 0 | W66: 0 | Y66: =(W66*'Population frame'!$B$35)/100 -> 0 | Z66: 0 | AB66: =(Z66*'Population frame'!$B$36)/100 -> 0 | AC66: 0 | AE66: =(AC66*'Population frame'!$B$37)/100 -> 0
A67: Feed and Forage: Alfalfa | B67: 0 | C67: =B67/100 -> 0 | D67: =C67*'Population frame'!$B$28 -> 0 | E67: 0 | F67: =E67/100 -> 0 | G67: =F67*'Population frame'!$B$30 -> 0 | H67: 2.2033095 | I67: =+H67/100 -> 0.022033095 | J67: =I67*'Population frame'!$B$31 -> 114125.46 | K67: 3.5271308 | L67: =K67/100 -> 0.035271308 | M67: =L67*'Population frame'!$B$34 -> 101714.27 | N67: 0 | P67: =(N67*'Population frame'!$B$29)/100 -> 0 | Q67: 0 | S67: =(Q67*'Population frame'!$B$32)/100 -> 0 | T67: 0 | V67: =(T67*'Population frame'!$B$33)/100 -> 0 | W67: 0 | Y67: =(W67*'Population frame'!$B$35)/100 -> 0 | Z67: 0.67220073 | AB67: =(Z67*'Population frame'!$B$36)/100 -> 183.90471 | AC67: 0 | AE67: =(AC67*'Population frame'!$B$37)/100 -> 0
A68: Feed and Forage: Industry by-products | B68: 1.1749255 | C68: =B68/100 -> 0.011749255 | D68: =C68*'Population frame'!$B$28 -> 10516.404 | E68: 2.3866392 | F68: =E68/100 -> 0.023866392 | G68: =F68*'Population frame'!$B$30 -> 85964.477 | H68: 4.9571249 | I68: =+H68/100 -> 0.049571249 | J68: =I68*'Population frame'!$B$31 -> 256765.64 | K68: 0.72073934 | L68: =K68/100 -> 0.0072073934 | M68: =L68*'Population frame'!$B$34 -> 20784.451 | N68: 4.0677977 | P68: =(N68*'Population frame'!$B$29)/100 -> 4866.9776 | Q68: 0 | S68: =(Q68*'Population frame'!$B$32)/100 -> 0 | T68: 0.60965498 | V68: =(T68*'Population frame'!$B$33)/100 -> 812.58474 | W68: 0 | Y68: =(W68*'Population frame'!$B$35)/100 -> 0 | Z68: 1.230134 | AB68: =(Z68*'Population frame'!$B$36)/100 -> 336.54745 | AC68: 7.3079109 | AE68: =(AC68*'Population frame'!$B$37)/100 -> 2280.9093
A69: Elephant grass, gaya, sasbaniya, alfalfa | B69: 0.39210628 | C69: =B69/100 -> 0.0039210628 | D69: =C69*'Population frame'!$B$28 -> 3509.6253 | E69: 0 | F69: =E69/100 -> 0 | G69: =F69*'Population frame'!$B$30 -> 0 | H69: 2.4238985 | I69: =+H69/100 -> 0.024238985 | J69: =I69*'Population frame'!$B$31 -> 125551.37 | K69: 5.2047802 | L69: =K69/100 -> 0.052047802 | M69: =L69*'Population frame'!$B$34 -> 150093.78 | N69: 0 | P69: =(N69*'Population frame'!$B$29)/100 -> 0 | Q69: 0 | S69: =(Q69*'Population frame'!$B$32)/100 -> 0 | T69: 0 | V69: =(T69*'Population frame'!$B$33)/100 -> 0 | W69: 0 | Y69: =(W69*'Population frame'!$B$35)/100 -> 0 | Z69: 0.67220073 | AB69: =(Z69*'Population frame'!$B$36)/100 -> 183.90471 | AC69: 0 | AE69: =(AC69*'Population frame'!$B$37)/100 -> 0
A71: Percentage of hh with at least 1 member benefitting from PSNP | B71: 0.19368653 | C71: 0.19368653 | D71: =C71*'Population frame'!$B$28 -> 173362.99 | E71: 0.14460407 | F71: 0.14460407 | G71: =F71*'Population frame'!$B$30 -> 520850.11 | H71: 0.036138343 | I71: 0.036138343 | J71: =I71*'Population frame'!$B$31 -> 187186.82 | K71: 0.068375717 | L71: 0.068375717 | M71: =L71*'Population frame'!$B$34 -> 197179.71
A74: CG-derived germplasm | B74: % Adopters | C74: Crop growing hh | D74: Absolute number | E74: % Adopters | F74: Crop growing hh | G74: Absolute number | H74: % Adopters | I74: Crop growing hh | J74: Absolute number | K74: % Adopters | L74: Crop growing hh | M74: Absolute number | N74: % Adopters | O74: Crop growing hh | P74: Absolute number | Q74: % Adopters | R74: Crop growing hh | S74: Absolute number | T74: % Adopters | U74: Crop growing hh | V74: Absolute number | W74: % Adopters | X74: Crop growing hh | Y74: Absolute number | Z74: % Adopters | AA74: Crop growing hh | AB74: Absolute number | AC74: % Adopters | AD74: Crop growing hh | AE74: Absolute number
...

Sheet Sheet1
A2: Lower Bound (DNA fingerprinting sample) | B2: 0.45346461 | C2: 0.75272452 | D2: =C2*B2*'Population frame'!$B$28 -> 305517.73 | E2: 0.36976139 | F2: 0.81845495 | G2: =F2*E2*'Population frame'!$B$30 -> 1090055.5 | H2: 0.49773344 | I2: 0.66809028 | J2: =I2*H2*'Population frame'!$B$31 -> 1722419.8 | K2: 0.5063226 | L2: 0.60136038 | M2: =L2*K2*'Population frame'!$B$34 -> 878056.46 | N2: 0 | O2: 0.09645493 | P2: - | Q2: 0 | R2: 0.11179212 | S2: - | T2: 0 | U2: 0.94809135 | V2: - | W2: 0 | X2: 0.58806112 | Y2: - | Z2: 0.47901491 | AA2: 0.87195674 | AB2: =(AA2*Z2*'Population frame'!$B$36) -> 11427.148 | AC2: 0.14814854 | AD2: 0.60998016 | AE2: =AD2*AC2*'Population frame'!$B$37 -> 2820.5114 | AF2: =SUM(AE2,AB2,M2,J2,G2,D2) -> 4010297.1
A3: Upper Bound (DNA fingerprinting sample) | B3: 0.96336342 | C3: 0.75272452 | D3: =C3*B3*'Population frame'!$B$28 -> 649057.5 | E3: 0.96596116 | F3: 0.81845495 | G3: =F3*E3*'Population frame'!$B$30 -> 2847650.6 | H3: 0.90624425 | I3: 0.66809028 | J3: =I3*H3*'Population frame'!$B$31 -> 3136082.3 | K3: 0.91337689 | L3: 0.60136038 | M3: =L3*K3*'Population frame'!$B$34 -> 1583963.4 | N3: 0 | O3: 0.09645493 | P3: - | Q3: 0 | R3: 0.11179212 | S3: - | T3: 0 | U3: 0.94809135 | V3: - | W3: 0 | X3: 0.58806112 | Y3: - | Z3: 0.98668517 | AA3: 0.87195674 | AB3: =(AA3*Z3*'Population frame'!$B$36) -> 23537.884 | AC3: 1 | AD3: 0.60998016 | AE3: =AD3*AC3*'Population frame'!$B$37 -> 19038.402 | AF3: =SUM(AE3,AB3,M3,J3,G3,D3) -> 8259330.1
B4: % Adopters | C4: Non-crop growing hh | D4: Absolute number | E4: % Adopters | F4: Non-crop growing hh | G4: Absolute number | H4: % Adopters | I4: Non-crop growing hh | J4: Absolute number | K4: % Adopters | L4: Non-crop growing hh | M4: Absolute number | N4: % Adopters | O4: Non-crop growing hh | P4: Absolute number | Q4: % Adopters | R4: Non-crop growing hh | S4: Absolute number | T4: % Adopters | U4: Non-crop growing hh | V4: Absolute number | W4: % Adopters | X4: Non-crop growing hh | Y4: Absolute number | Z4: % Adopters | AA4: Non-crop growing hh | AB4: Absolute number | AC4: % Adopters | AD4: Non-crop growing hh | AE4: Absolute number
A5: Upper Bound in DNA regions - other innovations | B5: 0.94733801 | C5: =1-C2 -> 0.24727548 | D5: =C5*B5*'Population frame'!$B$28 -> 209673.22 | E5: 0.96596116 | F5: =1-F2 -> 0.18154505 | G5: =F5*E5*'Population frame'!$B$30 -> 631649.74 | H5: 0.8655026 | I5: =1-I2 -> 0.33190972 | J5: =I5*H5*'Population frame'!$B$31 -> 1487974.2 | K5: 0.81217826 | L5: =1-L2 -> 0.39863962 | M5: =L5*K5*'Population frame'!$B$34 -> 933667.29 | N5: 0 | O5: =1-O2 -> 0.90354507 | P5: =O5*(N5*'Population frame'!$B$29) -> 0 | Q5: 0 | R5: =1-R2 -> 0.88820788 | S5: =R5*(Q5*'Population frame'!$B$32) -> 0 | T5: 0 | U5: =1-U2 -> 0.051908652 | V5: =U5*(T5*'Population frame'!$B$33) -> 0 | W5: 0 | X5: =1-X2 -> 0.41193888 | Y5: =X5*(W5*'Population frame'!$B$35) -> 0 | Z5: 0.96050807 | AA5: =1-AA2 -> 0.12804326 | AB5: =AA5*(Z5*'Population frame'!$B$36) -> 3364.7407 | AC5: 1 | AD5: =1-AD2 -> 0.39001984 | AE5: =AD5*AC5*'Population frame'!$B$37 -> 12173.108 | AF5: =SUM(AE5,AB5,M5,J5,G5,D5) -> 3278502.3
A6: Upper bound in all the other regions | B6: 0.62101004 | C6: - | E6: 0.78936725 | F6: - | H6: 0.68536469 | I6: - | K6: 0.69506215 | L6: - | N6: 0.16107812 | O6: - | P6: =(N6*'Population frame'!$B$29) -> 19272.434 | Q6: 0.13346259 | R6: - | S6: =(Q6*'Population frame'!$B$32) -> 84969.294 | T6: 0.86109107 | U6: - | V6: =(T6*'Population frame'!$B$33) -> 114771.38 | W6: 0.44835908 | X6: - | Y6: =(W6*'Population frame'!$B$35) -> 19813.347 | Z6: 0.772943 | AA6: - | AC6: 0.57192312 | AD6: -
A7: Upper Bound total by region | D7: =SUM(D3,D5,D6) -> 858730.71 | G7: =SUM(G3,G5,G6) -> 3479300.3 | J7: =SUM(J3,J5,J6) -> 4624056.5 | M7: =SUM(M3,M5,M6) -> 2517630.7 | P7: =SUM(P3,P5,P6) -> 19272.434 | S7: =SUM(S3,S5,S6) -> 84969.294 | V7: =SUM(V3,V5,V6) -> 114771.38 | Y7: =SUM(Y3,Y5,Y6) -> 19813.347 | AB7: =SUM(AB3,AB5,AB6) -> 26902.624 | AE7: =SUM(AE3,AE5,AE6) -> 31211.51
B9: Adoption | C9: Perc. HH | D9: Absolute number
A10: Lower bound (Maize) | B10: 0.79321305 | C10: 0.49467974 | D10: =(C10*'Population frame'!$B$28)*B10 -> 351213.28 | E10: 0.63843941 | F10: 0.60630559 | G10: =F10*E10*'Population frame'!$B$30 -> 1394259.2 | H10: 0.58432009 | I10: 0.52536831 | J10: =I10*H10*'Population frame'!$B$31 -> 1590090.1 | K10: 0.62898008 | L10: 0.39636759 | M10: =L10*K10*'Population frame'!$B$34 -> 718944.47 | N10: - | O10: 0.080286262 | P10: - | Q10: - | R10: 0 | S10: - | T10: - | U10: 0.90895875 | V10: - | W10: - | X10: 0.035700834 | Y10: - | Z10: 0.8017896 | AA10: 0.49194982 | AB10: =(AA10*Z10*'Population frame'!$B$36) -> 10791.333 | AC10: 1 | AD10: 0.19892222 | AE10: =AD10*AC10*'Population frame'!$B$37 -> 6208.663 | AF10: =SUM(AE10,AB10,M10,J10,G10,D10) -> 4071507.1
A11: Term 1
A12: Term 2
A13: Term 3

Sheet ESS3_rural
B1: Tigray | D1: Amhara | F1: Oromia | H1: SNNP | J1: Other regions
B2: Percentage | C2: Nb of households | D2: Percentage | E2: Nb of households | F2: Percentage | G2: Nb of households | H2: Percentage | I2: Nb of households | J2: Percentage | K2: Nb of households
A3: Sweet potato OFSP variety | B3: 0.33296414 | C3: =(B3*'Population frame'!$F$28)/100 -> 2727.3263 | D3: 0 | E3: =(D3*'Population frame'!$F$30)/100 -> 0 | F3: 1.4645426 | G3: =(F3*'Population frame'!$F$31)/100 -> 84631.26 | H3: 4.339897 | I3: =(H3*'Population frame'!$F$34)/100 -> 130187.67 | J3: 2.2700243 | K3: =(J3*'Population frame'!$F$38)/100 -> 18211.847
A4: Sweet potato Awassa83 variety | B4: 0 | C4: =(B4*'Population frame'!$F$28)/100 -> 0 | D4: 0.23108893 | E4: =(D4*'Population frame'!$F$30)/100 -> 9738.5587 | F4: 0.66167056 | G4: =(F4*'Population frame'!$F$31)/100 -> 38235.837 | H4: 10.768583 | I4: =(H4*'Population frame'!$F$34)/100 -> 323034.57 | J4: 0.15081271 | K4: =(J4*'Population frame'!$F$38)/100 -> 1209.9332
A5: Desi chickpea type | B5: 5.8349556 | C5: =(B5*'Population frame'!$F$28)/100 -> 47794.419 | D5: 5.018375 | E5: =(D5*'Population frame'!$F$30)/100 -> 211484.56 | F5: 5.7304377 | G5: =(F5*'Population frame'!$F$31)/100 -> 331143.77 | H5: 1.0431861 | I5: =(H5*'Population frame'!$F$34)/100 -> 31293.36 | J5: 3.4807146 | K5: =(J5*'Population frame'!$F$38)/100 -> 27924.917
A6: Kabuli chickpea type | B6: 3.5317612 | C6: =(B6*'Population frame'!$F$28)/100 -> 28928.836 | D6: 6.5597078 | E6: =(D6*'Population frame'!$F$30)/100 -> 276439.47 | F6: 6.071933 | G6: =(F6*'Population frame'!$F$31)/100 -> 350877.7 | H6: 0.53571634 | I6: =(H6*'Population frame'!$F$34)/100 -> 16070.349 | J6: 0.65750726 | K6: =(J6*'Population frame'!$F$38)/100 -> 5275.019
A7: Avocado tree | B7: 0.23707444 | C7: =(B7*'Population frame'!$F$28)/100 -> 1941.8888 | D7: 0.79860959 | E7: =(D7*'Population frame'!$F$30)/100 -> 33655.037 | F7: 11.624527 | G7: =(F7*'Population frame'!$F$31)/100 -> 671744.44 | H7: 23.814634 | I7: =(H7*'Population frame'!$F$34)/100 -> 714388.3 | J7: 3.7130173 | K7: =(J7*'Population frame'!$F$38)/100 -> 29788.625
A8: Papaya tree | B8: 1.3958693 | C8: =(B8*'Population frame'!$F$28)/100 -> 11433.637 | D8: 1.6799995 | E8: =(D8*'Population frame'!$F$30)/100 -> 70798.604 | F8: 6.0198426 | G8: =(F8*'Population frame'!$F$31)/100 -> 347867.56 | H8: 5.2826452 | I8: =(H8*'Population frame'!$F$34)/100 -> 158468.1 | J8: 9.6476 | K8: =(J8*'Population frame'!$F$38)/100 -> 77400.321
A9: Mango tree | B9: 1.5797243 | C9: =(B9*'Population frame'!$F$28)/100 -> 12939.602 | D9: 2.441064 | E9: =(D9*'Population frame'!$F$30)/100 -> 102871.42 | F9: 15.171169 | G9: =(F9*'Population frame'!$F$31)/100 -> 876693.58 | H9: 13.380464 | I9: =(H9*'Population frame'!$F$34)/100 -> 401385.43 | J9: 21.358925 | K9: =(J9*'Population frame'!$F$38)/100 -> 171357.4
A10: Field peas | B10: 9.0416109 | C10: =(B10*'Population frame'!$F$28)/100 -> 74060.296 | D10: 14.711502 | E10: =(D10*'Population frame'!$F$30)/100 -> 619972.71 | F10: 13.139421 | G10: =(F10*'Population frame'!$F$31)/100 -> 759285.36 | H10: 10.161662 | I10: =(H10*'Population frame'!$F$34)/100 -> 304828.21 | J10: 0 | K10: =(J10*'Population frame'!$F$38)/100 -> 0
A11: Sweetpotato | B11: 0.33296414 | C11: =(B11*'Population frame'!$F$28)/100 -> 2727.3263 | D11: 0.47640658 | E11: =(D11*'Population frame'!$F$30)/100 -> 20076.745 | F11: 8.325883 | G11: =(F11*'Population frame'!$F$31)/100 -> 481126.3 | H11: 17.958572 | I11: =(H11*'Population frame'!$F$34)/100 -> 538718.9 | J11: 10.774676 | K11: =(J11*'Population frame'!$F$38)/100 -> 86442.578
A13: River dispersion | B13: 2.8950901 | C13: =(B13*'Population frame'!$F$28)/100 -> 23713.83 | D13: 6.0369047 | E13: =(D13*'Population frame'!$F$30)/100 -> 254407.48 | F13: 5.0839862 | G13: =(F13*'Population frame'!$F$31)/100 -> 293787.4 | H13: 0.91920441 | I13: =(H13*'Population frame'!$F$34)/100 -> 27574.174 | J13: 8.0636491 | K13: =(J13*'Population frame'!$F$38)/100 -> 64692.673
A14: Treadle pump used for irrigation | B14: 0.64800128 | C14: =(B14*'Population frame'!$F$28)/100 -> 5307.8115 | D14: 0.1418618 | E14: =(D14*'Population frame'!$F$30)/100 -> 5978.3458 | F14: 0 | G14: =(F14*'Population frame'!$F$31)/100 -> 0 | H14: 0 | I14: =(H14*'Population frame'!$F$34)/100 -> 0 | J14: 0.032158047 | K14: =(J14*'Population frame'!$F$38)/100 -> 257.9961
A15: Motor pump used for irrigation | B15: 4.0268407 | C15: =(B15*'Population frame'!$F$28)/100 -> 32984.058 | D15: 1.8700215 | E15: =(D15*'Population frame'!$F$30)/100 -> 78806.519 | F15: 0.38187184 | G15: =(F15*'Population frame'!$F$31)/100 -> 22067.159 | H15: 0.5746399 | I15: =(H15*'Population frame'!$F$34)/100 -> 17237.973 | J15: 6.2803757 | K15: =(J15*'Population frame'!$F$38)/100 -> 50385.909
... A40: Elephant grass, gaya, sasbaniya, alfalfa | B40: 0.59732125 | C40: =(B40*'Population frame'!$F$28)/100 -> 4892.6888 | D40: 0.088830781 | E40: =(D40*'Population frame'!$F$30)/100 -> 3743.5103 | F40: 0.72181056 | G40: =(F40*'Population frame'!$F$31)/100 -> 41711.137 | H40: 2.0269481 | I40: =(H40*'Population frame'!$F$34)/100 -> 60804.127 | J40: 5.9225519 | K40: =(J40*'Population frame'!$F$38)/100 -> 47515.177
A42: PSNP | B42: =0.221867577067878*100 -> 22.186758 | C42: =(B42*'Population frame'!$F$28) -> 18173286 | D42: =0.0924127314204457*100 -> 9.2412731 | E42: =(D42*'Population frame'!$F$30) -> 38944610 | F42: =0.0500925667671379*100 -> 5.0092567 | G42: =(F42*'Population frame'!$F$31) -> 28946901 | H42: =0.0886249852805724*100 -> 8.8624985 | I42: =(H42*'Population frame'!$F$34) -> 26585608 | J42: =0.139453342442868*100 -> 13.945334 | K42: =(J42*'Population frame'!$F$38) -> 11187999
A45: Lower Bound | B45: 0.034914183 | C45: =(B45*'Population frame'!$F$28) -> 28598.385 | D45: 0.063115351 | E45: =(D45*'Population frame'!$F$30) -> 265980.96 | F45: 0.077605763 | G45: =(F45*'Population frame'!$F$31) -> 448459.02 | H45: 0.1446819 | I45: =(H45*'Population frame'!$F$34) -> 434014.88 | J45: 0.015543844 | K45: =(J45*'Population frame'!$F$38) -> 12470.443
A47: Upper Bound | B47: 0.87372681 | C47: =(B47*'Population frame'!$F$28) -> 715674.08 | D47: 0.8328415 | E47: =(D47*'Population frame'!$F$30) -> 3509764 | F47: 0.78785243 | G47: =(F47*'Population frame'!$F$31) -> 4552748.6 | H47: 0.69798343 | I47: =(H47*'Population frame'!$F$34) -> 2093801.6 | J47: 0.60603073 | K47: =(J47*'Population frame'!$F$38) -> 486203.55
A50: Note:
A51: Lower bound includes: Desi and Kabuli chickpea, OFSP and Awassa83
A52: Upper bound: all the rest of the innovations
